{
  "cells": [
    {
      "metadata": {},
      "cell_type": "markdown",
      "source": "# Section 3.1: Error Handling\n* try...except\n* try...except...except...\n* try...except...else\n* try...finally\n* raise\n\n### Students will be able to:\n* Differentiate between exception types and recognize their meaning\n* Handle a raised exception\n* Handle different exception types\n* Use `else` and `finally` to perform clean-up actions \n* Raise a forced exception of a specific type"
    },
    {
      "metadata": {},
      "cell_type": "markdown",
      "source": "---\n<font size=\"6\" color=\"#00A0B2\"  face=\"verdana\"> <B>Concepts</B></font>  \n\n\n## Exception Types\n\n\n[![view video](https://iajupyterprodblobs.blob.core.windows.net/imagecontainer/common/play_video.png)](https://www.youtube.com/watch?v=u6MDIbo6210)\n\n\nYou have seen many error messages generated by your programs. In Python (and many other languages), errors are also called exceptions, and they have many types. Let's examine an exception (error) and discuss the error message associated with it:\n\n```python\n>>> 5/0\nTraceback (most recent call last):\n  File \"<stdin>\", line 1, in <module>\nZeroDivisionError: division by zero\n```\n\nThe last line indicates that the exception is of type `ZeroDivisionError`, and also indicates that it was raised by a division by zero (5/0), which is mathematically intractable. The penultimate line indicates that the exception source is in line 1 of your code. If the expression was part of a larger code, the line number would reflect the source of the error.\n\nIn addition to `ZeroDivisionError`, the Python standard library supports many exception types. In the following examples, you will see some exception types that you might have encountered already. More information about the built-in exception types is available from the Python Documentation site at https://docs.python.org/3/library/exceptions.html#bltin-exceptions.\n\nGenerally speaking, when Python encounters an error of any type it raises an exception. The exception then propagates through the calling function and upper-level functions until it's dealt with. As a programmer, you can decide what to do when an exception is raised--you can either pass it to another level or handle it. In the next section, you will explore methods of handling different types of exceptions."
    },
    {
      "metadata": {},
      "cell_type": "markdown",
      "source": "---\n<font size=\"6\" color=\"#00A0B2\"  face=\"verdana\"> <B>Examples</B></font>\n\n### `IndexError`\nRaised by trying to access (or write into) an out-of-range index of a sequence (i.e. list)."
    },
    {
      "metadata": {
        "trusted": true
      },
      "cell_type": "code",
      "source": "lst = [0, 1, 2]\nprint(lst[30])",
      "execution_count": 27,
      "outputs": [
        {
          "output_type": "error",
          "ename": "IndexError",
          "evalue": "list index out of range",
          "traceback": [
            "\u001b[0;31m---------------------------------------------------------------------------\u001b[0m",
            "\u001b[0;31mIndexError\u001b[0m                                Traceback (most recent call last)",
            "\u001b[0;32m<ipython-input-27-1c4b5340a3bd>\u001b[0m in \u001b[0;36m<module>\u001b[0;34m()\u001b[0m\n\u001b[1;32m      1\u001b[0m \u001b[0mlst\u001b[0m \u001b[0;34m=\u001b[0m \u001b[0;34m[\u001b[0m\u001b[0;36m0\u001b[0m\u001b[0;34m,\u001b[0m \u001b[0;36m1\u001b[0m\u001b[0;34m,\u001b[0m \u001b[0;36m2\u001b[0m\u001b[0;34m]\u001b[0m\u001b[0;34m\u001b[0m\u001b[0m\n\u001b[0;32m----> 2\u001b[0;31m \u001b[0mprint\u001b[0m\u001b[0;34m(\u001b[0m\u001b[0mlst\u001b[0m\u001b[0;34m[\u001b[0m\u001b[0;36m30\u001b[0m\u001b[0;34m]\u001b[0m\u001b[0;34m)\u001b[0m\u001b[0;34m\u001b[0m\u001b[0m\n\u001b[0m",
            "\u001b[0;31mIndexError\u001b[0m: list index out of range"
          ]
        }
      ]
    },
    {
      "metadata": {},
      "cell_type": "markdown",
      "source": "### `NameError`\nRaised by accessing an unspecified (undefined) variable."
    },
    {
      "metadata": {
        "trusted": true
      },
      "cell_type": "code",
      "source": "# y is not defined anywhere\nprint(y)",
      "execution_count": 33,
      "outputs": [
        {
          "output_type": "error",
          "ename": "NameError",
          "evalue": "name 'y' is not defined",
          "traceback": [
            "\u001b[0;31m---------------------------------------------------------------------------\u001b[0m",
            "\u001b[0;31mNameError\u001b[0m                                 Traceback (most recent call last)",
            "\u001b[0;32m<ipython-input-33-4a90c53d6cdd>\u001b[0m in \u001b[0;36m<module>\u001b[0;34m()\u001b[0m\n\u001b[1;32m      1\u001b[0m \u001b[0;31m# y is not defined anywhere\u001b[0m\u001b[0;34m\u001b[0m\u001b[0;34m\u001b[0m\u001b[0m\n\u001b[0;32m----> 2\u001b[0;31m \u001b[0mprint\u001b[0m\u001b[0;34m(\u001b[0m\u001b[0my\u001b[0m\u001b[0;34m)\u001b[0m\u001b[0;34m\u001b[0m\u001b[0m\n\u001b[0m",
            "\u001b[0;31mNameError\u001b[0m: name 'y' is not defined"
          ]
        }
      ]
    },
    {
      "metadata": {},
      "cell_type": "markdown",
      "source": "### `TypeError`\nRaised when performing an unsupported operation on a specific type, such us dividing strings."
    },
    {
      "metadata": {
        "trusted": true
      },
      "cell_type": "code",
      "source": "s1 = 'Word1'\ns2 = 'Word2'\ns1/s2",
      "execution_count": 26,
      "outputs": [
        {
          "output_type": "error",
          "ename": "TypeError",
          "evalue": "unsupported operand type(s) for /: 'str' and 'str'",
          "traceback": [
            "\u001b[0;31m---------------------------------------------------------------------------\u001b[0m",
            "\u001b[0;31mTypeError\u001b[0m                                 Traceback (most recent call last)",
            "\u001b[0;32m<ipython-input-26-4ccc95d0b19d>\u001b[0m in \u001b[0;36m<module>\u001b[0;34m()\u001b[0m\n\u001b[1;32m      1\u001b[0m \u001b[0ms1\u001b[0m \u001b[0;34m=\u001b[0m \u001b[0;34m'Word1'\u001b[0m\u001b[0;34m\u001b[0m\u001b[0m\n\u001b[1;32m      2\u001b[0m \u001b[0ms2\u001b[0m \u001b[0;34m=\u001b[0m \u001b[0;34m'Word2'\u001b[0m\u001b[0;34m\u001b[0m\u001b[0m\n\u001b[0;32m----> 3\u001b[0;31m \u001b[0ms1\u001b[0m\u001b[0;34m/\u001b[0m\u001b[0ms2\u001b[0m\u001b[0;34m\u001b[0m\u001b[0m\n\u001b[0m",
            "\u001b[0;31mTypeError\u001b[0m: unsupported operand type(s) for /: 'str' and 'str'"
          ]
        }
      ]
    },
    {
      "metadata": {},
      "cell_type": "markdown",
      "source": "---\n<font size=\"6\" color=\"#B24C00\"  face=\"verdana\"> <B>Task 1</B></font>\n\n## Exception Types\n\nBefore completing this task, visit the Python Documentation site at https://docs.python.org/3/library/exceptions.html#bltin-exceptions to learn about the built-in exception types."
    },
    {
      "metadata": {
        "trusted": true
      },
      "cell_type": "code",
      "source": "# [ ] Write an expression to raise a `ModuleNotFoundError` exception\nimport za\n",
      "execution_count": 15,
      "outputs": [
        {
          "output_type": "error",
          "ename": "ImportError",
          "evalue": "No module named 'za'",
          "traceback": [
            "\u001b[0;31m---------------------------------------------------------------------------\u001b[0m",
            "\u001b[0;31mImportError\u001b[0m                               Traceback (most recent call last)",
            "\u001b[0;32m<ipython-input-15-f41851f10f9d>\u001b[0m in \u001b[0;36m<module>\u001b[0;34m()\u001b[0m\n\u001b[1;32m      1\u001b[0m \u001b[0;31m# [ ] Write an expression to raise a `ModuleNotFoundError` exception\u001b[0m\u001b[0;34m\u001b[0m\u001b[0;34m\u001b[0m\u001b[0m\n\u001b[0;32m----> 2\u001b[0;31m \u001b[0;32mimport\u001b[0m \u001b[0mza\u001b[0m\u001b[0;34m\u001b[0m\u001b[0m\n\u001b[0m",
            "\u001b[0;31mImportError\u001b[0m: No module named 'za'"
          ]
        }
      ]
    },
    {
      "metadata": {
        "trusted": true
      },
      "cell_type": "code",
      "source": "# [ ] Write an expression to raise a `ModuleNotFoundError` exception\nfrom math import a",
      "execution_count": 16,
      "outputs": [
        {
          "output_type": "error",
          "ename": "ImportError",
          "evalue": "cannot import name 'a'",
          "traceback": [
            "\u001b[0;31m---------------------------------------------------------------------------\u001b[0m",
            "\u001b[0;31mImportError\u001b[0m                               Traceback (most recent call last)",
            "\u001b[0;32m<ipython-input-16-3fb07729cd63>\u001b[0m in \u001b[0;36m<module>\u001b[0;34m()\u001b[0m\n\u001b[1;32m      1\u001b[0m \u001b[0;31m# [ ] Write an expression to raise a `ModuleNotFoundError` exception\u001b[0m\u001b[0;34m\u001b[0m\u001b[0;34m\u001b[0m\u001b[0m\n\u001b[0;32m----> 2\u001b[0;31m \u001b[0;32mfrom\u001b[0m \u001b[0mmath\u001b[0m \u001b[0;32mimport\u001b[0m \u001b[0ma\u001b[0m\u001b[0;34m\u001b[0m\u001b[0m\n\u001b[0m",
            "\u001b[0;31mImportError\u001b[0m: cannot import name 'a'"
          ]
        }
      ]
    },
    {
      "metadata": {},
      "cell_type": "markdown",
      "source": "---\n<font size=\"6\" color=\"#00A0B2\"  face=\"verdana\"> <B>Concepts</B></font>  \n\n\n## Handling Exceptions\n\n\n[![view video](https://iajupyterprodblobs.blob.core.windows.net/imagecontainer/common/play_video.png)](https://www.youtube.com/watch?v=_Caw2CSQvaM)\n\nUp to this point in the course, if your code encountered an error it stopped execution and displayed an error message. You had to read the error message, understand the reason it was generated, and fix the code. \n\nThere are situations in which you want your code to continue execution or display a friendly message to the user despite an error that you might or might not anticipate in advance. It is possible to modify your program to handle specific exceptions and to continue execution without stopping. The process is called exception handling, and can be done using a `try...except` statement with the following syntax:\n\n```python\ntry:\n    code that may raise an exception\nexcept ExceptionType:\n    code block to handle exception\n```\n\n#### Handling multiple exceptions\nYour program can raise exceptions of different types. You can use the `try...except` statement to handle each of the types differently by adding another `except` clause and its associated code at the end:\n\n```python\ntry:\n    code that may raise an exception\nexcept ExceptionType_1:\n    code block to handle exception of type ExceptionType_1\nexcept ExceptionType_2:\n    code block to handle exception of type ExceptionType_2\n```\n\nWhen an exception is raised, the rest of the code inside the `try` block is ignored and the execution jumps to the relevant `except` code block and executes it. Then the program continues normal execution.\n\n#### Handling unexpected exceptions\nIf your code encounters an exception you did not anticipate or explicitly handle, your program will stop execution and display an error message. You can handle unexpected exceptions using an `except` clause without specifying the exception type:\n\n```python\ntry:\n    code that may raise an exception\nexcept ExceptionType_1:\n    code block to handle exception of type ExceptionType_1\nexcept ExceptionType_2:\n    code block to handle exception of type ExceptionType_2\nexcept:\n    code block to handle unexpected exceptions of any type\n```\n\n#### Handling exceptions raised by other functions\nWhen a function raises an exception without handling it, the caller function must handle the exception or raise it up another level. For example, the `sqrt` function from the `math` module expect a positive number for an argument. Passing a negative number to `sqrt` will raise a `ValueError` exception. The `sqrt` function doesn't handle the exception internally, so your code should handle it or raise it to an upper level.\n\n#### Error messages\nThe error message associated with a raised exception can be stored in a variable using (`as exception_object:`) in the `except` clause, right after the exception type:\n\n```python\ntry:\n    code that may raise an exception\nexcept ExceptionType_1 as exception_object:\n    code block to handle exception of type ExceptionType_1\nexcept ExceptionType_2 as exception_object:\n    code block to handle exception of type ExceptionType_2\nexcept Exception as exception_object:\n    code block to handle unexpected exceptions of any type\n```\n\nNOTE: For unexpected exceptions, use (`Exception as exception_object:`) to store the error message."
    },
    {
      "metadata": {},
      "cell_type": "markdown",
      "source": "---\n<font size=\"6\" color=\"#00A0B2\"  face=\"verdana\"> <B>Examples</B></font>\n"
    },
    {
      "metadata": {},
      "cell_type": "markdown",
      "source": "### Handling a single exception\n\nIn this example, you will see how to handle the division by zero exception you saw earlier. You will see that the program does not terminate when it encounters the error, and continues running as expected."
    },
    {
      "metadata": {
        "trusted": true
      },
      "cell_type": "code",
      "source": "try:\n    5/0\nexcept ZeroDivisionError:\n    print(\"Cannot divide by zero!\")\n\nprint(\"Program is still running\")",
      "execution_count": 34,
      "outputs": [
        {
          "output_type": "stream",
          "text": "Cannot divide by zero!\nProgram is still running\n",
          "name": "stdout"
        }
      ]
    },
    {
      "metadata": {},
      "cell_type": "markdown",
      "source": "### Handling multiple exceptions\nThe following example shows a program that divides all the elements of a list by their associated indices. You can see that when an exception is raised, the program ignores the rest of the code inside the `try` block (`print(\"print executed\")`), jumps to the relevant `except` code block, and executes it. Then the program continues normal execution, so it goes through the next loop iteration and executes the `try` block again."
    },
    {
      "metadata": {
        "trusted": true
      },
      "cell_type": "code",
      "source": "lst = ['text', 5, 12]\nfor i in range(5):\n    try:        \n        print(lst[i] / i)\n        print(\"print executed\")\n    except TypeError:\n        print(\"Cannot divide strings\")\n    except IndexError:\n        print(\"Cannot access out of range elements\")",
      "execution_count": 35,
      "outputs": [
        {
          "output_type": "stream",
          "text": "Cannot divide strings\n5.0\nprint executed\n6.0\nprint executed\nCannot access out of range elements\nCannot access out of range elements\n",
          "name": "stdout"
        }
      ]
    },
    {
      "metadata": {},
      "cell_type": "markdown",
      "source": "### Handling unexpected exceptions\n\nIf a program encounters unhandled exceptions, it will terminate and display an error message."
    },
    {
      "metadata": {
        "trusted": true
      },
      "cell_type": "code",
      "source": "# Without handling unexpected exception\n\nx = [5]\ntry:\n    x / 0\nexcept ZeroDivisionError:\n    print(\"Cannot divide by zero!\")\n    ",
      "execution_count": 36,
      "outputs": [
        {
          "output_type": "error",
          "ename": "TypeError",
          "evalue": "unsupported operand type(s) for /: 'list' and 'int'",
          "traceback": [
            "\u001b[0;31m---------------------------------------------------------------------------\u001b[0m",
            "\u001b[0;31mTypeError\u001b[0m                                 Traceback (most recent call last)",
            "\u001b[0;32m<ipython-input-36-12007c7d648c>\u001b[0m in \u001b[0;36m<module>\u001b[0;34m()\u001b[0m\n\u001b[1;32m      3\u001b[0m \u001b[0mx\u001b[0m \u001b[0;34m=\u001b[0m \u001b[0;34m[\u001b[0m\u001b[0;36m5\u001b[0m\u001b[0;34m]\u001b[0m\u001b[0;34m\u001b[0m\u001b[0m\n\u001b[1;32m      4\u001b[0m \u001b[0;32mtry\u001b[0m\u001b[0;34m:\u001b[0m\u001b[0;34m\u001b[0m\u001b[0m\n\u001b[0;32m----> 5\u001b[0;31m     \u001b[0mx\u001b[0m \u001b[0;34m/\u001b[0m \u001b[0;36m0\u001b[0m\u001b[0;34m\u001b[0m\u001b[0m\n\u001b[0m\u001b[1;32m      6\u001b[0m \u001b[0;32mexcept\u001b[0m \u001b[0mZeroDivisionError\u001b[0m\u001b[0;34m:\u001b[0m\u001b[0;34m\u001b[0m\u001b[0m\n\u001b[1;32m      7\u001b[0m     \u001b[0mprint\u001b[0m\u001b[0;34m(\u001b[0m\u001b[0;34m\"Cannot divide by zero!\"\u001b[0m\u001b[0;34m)\u001b[0m\u001b[0;34m\u001b[0m\u001b[0m\n",
            "\u001b[0;31mTypeError\u001b[0m: unsupported operand type(s) for /: 'list' and 'int'"
          ]
        }
      ]
    },
    {
      "metadata": {
        "trusted": true
      },
      "cell_type": "code",
      "source": "# Handling unexpected exception\n\nx = [5]\ntry:\n    x / 0\nexcept ZeroDivisionError:\n    print(\"Cannot divide by zero!\")\nexcept:\n    print(\"Unexpected error\")",
      "execution_count": 37,
      "outputs": [
        {
          "output_type": "stream",
          "text": "Unexpected error\n",
          "name": "stdout"
        }
      ]
    },
    {
      "metadata": {},
      "cell_type": "markdown",
      "source": "### Handling multiple and unexpected exceptions\n\nIn the following example, the number 12 is divided by the elements of `old_lst`. The code encounters several exceptions (`TypeError`, `ZeroDivisionError`, and `IndexError`) that it handles explicitly by type. The code never stops running. When an unexpected exception (`IndexError`) is raised, the last `except` clause handles it by displaying a friendly error message."
    },
    {
      "metadata": {
        "trusted": true
      },
      "cell_type": "code",
      "source": "old_lst = [6, 'word', [2, 5], 0, 3]\nnew_lst = []\n\nfor i in range(6):\n    try:\n        tmp = 12 / old_lst[i]\n        new_lst.append(tmp)\n        print(\"List appended with\", tmp)\n    except TypeError:\n        print(\"Cannot divide {0:d} by {1:}\".format(12, type(old_lst[i])))\n    except ZeroDivisionError:\n        print(\"Cannot divide by 0\")\n    # Handling unexpected exceptions, by showing the associated error message\n    except Exception as exception_object:\n        print(\"Unexpected error: {0:}\".format(exception_object))\n        \nprint()\nprint(\"The new list is:\", new_lst)\n        ",
      "execution_count": 42,
      "outputs": [
        {
          "output_type": "stream",
          "text": "List appended with 2.0\nCannot divide 12 by <class 'str'>\nCannot divide 12 by <class 'list'>\nCannot divide by 0\nList appended with 4.0\nUnexpected error: list index out of range\n\nThe new list is: [2.0, 4.0]\n",
          "name": "stdout"
        }
      ]
    },
    {
      "metadata": {},
      "cell_type": "markdown",
      "source": "### Handling exceptions raised by other functions\nThe `sqrt` function from the `math` module expect a positive number for an argument. Passing a negative number to `sqrt` will raise a `ValueError` exception. The `sqrt` function doesn't handle the exception internally, so your code should handle it or raise it to an upper level."
    },
    {
      "metadata": {
        "trusted": true
      },
      "cell_type": "code",
      "source": "# Without exception handling\n\nfrom math import sqrt\nx = -3\nsqrt(x)",
      "execution_count": 43,
      "outputs": [
        {
          "output_type": "error",
          "ename": "ValueError",
          "evalue": "math domain error",
          "traceback": [
            "\u001b[0;31m---------------------------------------------------------------------------\u001b[0m",
            "\u001b[0;31mValueError\u001b[0m                                Traceback (most recent call last)",
            "\u001b[0;32m<ipython-input-43-ecd58ebb1b24>\u001b[0m in \u001b[0;36m<module>\u001b[0;34m()\u001b[0m\n\u001b[1;32m      3\u001b[0m \u001b[0;32mfrom\u001b[0m \u001b[0mmath\u001b[0m \u001b[0;32mimport\u001b[0m \u001b[0msqrt\u001b[0m\u001b[0;34m\u001b[0m\u001b[0m\n\u001b[1;32m      4\u001b[0m \u001b[0mx\u001b[0m \u001b[0;34m=\u001b[0m \u001b[0;34m-\u001b[0m\u001b[0;36m3\u001b[0m\u001b[0;34m\u001b[0m\u001b[0m\n\u001b[0;32m----> 5\u001b[0;31m \u001b[0msqrt\u001b[0m\u001b[0;34m(\u001b[0m\u001b[0mx\u001b[0m\u001b[0;34m)\u001b[0m\u001b[0;34m\u001b[0m\u001b[0m\n\u001b[0m",
            "\u001b[0;31mValueError\u001b[0m: math domain error"
          ]
        }
      ]
    },
    {
      "metadata": {
        "trusted": true
      },
      "cell_type": "code",
      "source": "# With exception handling\n\nfrom math import sqrt\nx = -3\ntry:\n    sqrt(x)\nexcept ValueError as exception_object: # Storing the error message in exception_object\n    print(exception_object)",
      "execution_count": 1,
      "outputs": [
        {
          "output_type": "stream",
          "text": "math domain error\n",
          "name": "stdout"
        }
      ]
    },
    {
      "metadata": {},
      "cell_type": "markdown",
      "source": "---\n<font size=\"6\" color=\"#B24C00\"  face=\"verdana\"> <B>Task 2</B></font>\n\n## Handling Exceptions\n"
    },
    {
      "metadata": {
        "trusted": true
      },
      "cell_type": "code",
      "source": "# [ ] The following program adds `lst1` to `lst2` element by element\n# Find all exceptions that will be generated by this program,\n# then handle the exceptions by displaying meaningful messages.\n# You should also handle unexpected exceptions.\n\nlst1 = [-4, -5, 6, [6], \"hello\"]\nlst2 = [5, 16, [6], \"hello\", \"goodbye\"]\n\nfor i in range(7):\n    try:\n        print(lst1[i] + lst2[i])\n        print(\"executed!\")\n    except TypeError:\n        print(\"Sorry!A string cannot be added with another integer or vise-versa!\")\n    except IndexError:\n        pass\n    except:\n        print(\"Unexpected error!!\")\nprint(\"Thank You\")",
      "execution_count": 2,
      "outputs": [
        {
          "output_type": "stream",
          "text": "1\nexecuted!\n11\nexecuted!\nSorry!A string cannot be added with another integer or vise-versa!\nSorry!A string cannot be added with another integer or vise-versa!\nhellogoodbye\nexecuted!\nThank You\n",
          "name": "stdout"
        }
      ]
    },
    {
      "metadata": {
        "trusted": true
      },
      "cell_type": "code",
      "source": "# [ ] The following program asks the user for an integer then prints the result of dividing it by 2.\n# If the user enters an invalid value (i.e. \"4.3\" or \"Hello\"), the program terminates.\n# Use exception handling to deal with unexpected user input and display a meaningful message.\n\nx = input(\"Enter an integer: \")\ntry:\n    x = int(x)\n    print(\"{:d} / 2 = {:.2f}\".format(x, x / 2))\n    print(\"Done!\")\nexcept ValueError:\n    print(\"please do enter an integer next time!!!!\")",
      "execution_count": 3,
      "outputs": [
        {
          "output_type": "stream",
          "name": "stdout",
          "text": "Enter an integer: 5\n5 / 2 = 2.50\nDone!\n"
        }
      ]
    },
    {
      "metadata": {},
      "cell_type": "markdown",
      "source": "---\n<font size=\"6\" color=\"#00A0B2\"  face=\"verdana\"> <B>Concepts</B></font>  \n\n\n## `else` and `finally`\n\n\n[![view video](https://iajupyterprodblobs.blob.core.windows.net/imagecontainer/common/play_video.png)](https://www.youtube.com/watch?v=JdxAV3hb634)\n\n#### `else`\n\nOccasionally, you might want to run some code when a `try` statement does not raise an exception. This can be achieved using the optional `else` statement. The code block within the `else` statement will be executed when the code reaches the end of the `try` code block without raising any exceptions. \n\nUse the following syntax for an `else` clause:\n\n```python\ntry:\n    code that may raise an exception\nexcept ExceptionType_1:\n    code block to handle exception of type ExceptionType_1\nexcept ExceptionType_2:\n    code block to handle exception of type ExceptionType_2\nexcept:\n    code block to handle unexpected exceptions of any type\nelse:\n    code block to run when no exceptions were raised\n```\n\n#### `finally`\n\nSometimes you need to execute some code whether or not an exception has been raised. The optional `finally` clause can handle this situation and run a code block whenever you exit a `try...except` statement. The code block within the `finally` statement will be executed in the following situations: when an exception has been raised, upon reaching the end of the `try` statement without raising an exception, and when exiting a `try` statement by using `break`, `continue`, or `return`.\n\n`finally` is typically used for clean-up actions, i.e. releasing external resources such as files or network connections.\n\nUse the following syntax for a `finally` clause:\n\n```python\ntry:\n    code that may raise an exception\nexcept ExceptionType_1:\n    code block to handle exception of type ExceptionType_1\nexcept ExceptionType_2:\n    code block to handle exception of type ExceptionType_2\nexcept:\n    code block to handle unexpected exceptions of any type\nfinally:\n    code that will always execute whether an exception was raised or not\n```\n\nNOTE: Though Python allows you to use an `else` clause followed by a `finally` clause, the code generated will be difficult to understand and you should avoid using these two clauses together.\n"
    },
    {
      "metadata": {},
      "cell_type": "markdown",
      "source": "---\n<font size=\"6\" color=\"#00A0B2\"  face=\"verdana\"> <B>Examples</B></font>\n\n### `else`\nIn this example, the code performs 3 &divide; 2 successfully and without exceptions. Therefore, the `else` clause will be executed, displaying the \"All good\" message."
    },
    {
      "metadata": {
        "trusted": true
      },
      "cell_type": "code",
      "source": "x = 3\ny = 2\ntry:\n    print(x/y)\nexcept ZeroDivisionError:\n    print(\"Cannot divide by zero\")\nelse:\n    print(\"All good! No exceptions were raised.\")",
      "execution_count": 4,
      "outputs": [
        {
          "output_type": "stream",
          "text": "1.5\nAll good! No exceptions were raised.\n",
          "name": "stdout"
        }
      ]
    },
    {
      "metadata": {},
      "cell_type": "markdown",
      "source": "### `finally`\nIn the following examples, the code performs 3 &divide; 2, which does NOT raise an exception, and then performs 3 &divide; 0, which does raise an exception. In both cases, the `finally` clause will be executed."
    },
    {
      "metadata": {
        "trusted": true
      },
      "cell_type": "code",
      "source": "x = 3\ny = 2\ntry:\n    print(x/y)\nexcept ZeroDivisionError:\n    print(\"Cannot divide by zero\")\nfinally:\n    print(\"Code that will run whether an exception was raised or not\")",
      "execution_count": 5,
      "outputs": [
        {
          "output_type": "stream",
          "text": "1.5\nCode that will run whether an exception was raised or not\n",
          "name": "stdout"
        }
      ]
    },
    {
      "metadata": {
        "trusted": true
      },
      "cell_type": "code",
      "source": "x = 3\ny = 0\ntry:\n    print(x/y)\nexcept ZeroDivisionError:\n    print(\"Cannot divide by zero\")\nfinally:\n    print(\"Code that will run whether an exception was raised or not\")",
      "execution_count": 6,
      "outputs": [
        {
          "output_type": "stream",
          "text": "Cannot divide by zero\nCode that will run whether an exception was raised or not\n",
          "name": "stdout"
        }
      ]
    },
    {
      "metadata": {},
      "cell_type": "markdown",
      "source": "---\n<font size=\"6\" color=\"#B24C00\"  face=\"verdana\"> <B>Task 3</B></font>\n\n## `else` and `finally`"
    },
    {
      "metadata": {},
      "cell_type": "markdown",
      "source": "### `else`"
    },
    {
      "metadata": {
        "trusted": true
      },
      "cell_type": "code",
      "source": "# [ ] The following program asks the user for an integer `x` then assigns `y` as the result of dividing `x` by 2.\n# If the user enters an invalid value (i.e. \"4.3\" or \"Hello\"), the program terminates.\n# Use exception handling to deal with unexpected user inputs, then use an `else` clause to calculate the value of `y`.\ntry:\n    x = input(\"Enter an integer: \")\n    y = None\n    x = int(x)\n    y = x / 2\n\n    if y is not None:\n        print(\"No exceptions were raised, you can use y =\", y)\n    else:\n        print(\"An exception was raised, y cannot be used\")\nexcept ValueError:\n    print(\"Exception:Only Integers!\")\nelse:\n    print(\"y is\",y)",
      "execution_count": 10,
      "outputs": [
        {
          "output_type": "stream",
          "name": "stdout",
          "text": "Enter an integer: 2\nNo exceptions were raised, you can use y = 1.0\ny is 1.0\n"
        }
      ]
    },
    {
      "metadata": {},
      "cell_type": "markdown",
      "source": "### `finally`"
    },
    {
      "metadata": {
        "trusted": true
      },
      "cell_type": "code",
      "source": "# [ ] The following program tries to write to a file opened for reading.\n# The program will terminate before closing the file, and the file resources will not be released.\n# Use exception handling with a `finally` clause to make sure the file is closed.\n# Open a text file for reading\ntry:\n    f = open(\"parent_dir/text_file.txt\", 'r')\n    # Try to write to a file open for reading (will raise an exception)\nexcept:\n    f.write(\"This string will not be written\")\nfinally:\n# Close the file (will not be reached if an exception was raised)\n    f.close()\n    print(\"File closed\")",
      "execution_count": 1,
      "outputs": [
        {
          "output_type": "stream",
          "text": "File closed\n",
          "name": "stdout"
        }
      ]
    },
    {
      "metadata": {},
      "cell_type": "markdown",
      "source": "---\n<font size=\"6\" color=\"#00A0B2\"  face=\"verdana\"> <B>Concepts</B></font>  \n\n\n## Raising Exceptions\n\n\n[![view video](https://iajupyterprodblobs.blob.core.windows.net/imagecontainer/common/play_video.png)](https://www.youtube.com/watch?v=XphAylGJSYI)\n\nIn the previous examples, you saw that Python supports many built-in exceptions. As a programmer, you can also define and raise a forced exception using the `raise` statement. The syntax for this statement is:\n\n```python\nraise ExceptionType(\"Error Message\")\n```\n\n* The `ExceptionType` can be one of the built-in exceptions supported by Python, or you can define a new type. \n* The `Error Message` will be associated with this exception when it is raised."
    },
    {
      "metadata": {},
      "cell_type": "markdown",
      "source": "---\n<font size=\"6\" color=\"#00A0B2\"  face=\"verdana\"> <B>Examples</B></font>\n\nYou can raise an exception when a user does not provide a valid response to a request for input between 1 and 10. However, numbers outside the range do not necessarily generate errors in Python, so you have to explicitly force a raised exception.\n\nTest the code with the following inputs:\n* 100 (an out-of-range value that should raise the forced exception)\n* text (a string value that will cause the `int()` function to raise a different `ValueError`)\n* 4 (a valid number within the range)"
    },
    {
      "metadata": {
        "trusted": true
      },
      "cell_type": "code",
      "source": "valid = False\nwhile not valid:\n    try:\n        x = int(input(\"Enter a number between 1 and 10: \"))\n        if ((x < 1) or (x > 10)):\n            raise ValueError(\"The number is outside of the acceptable range\")\n        valid = True\n    except ValueError as except_object:\n        print(\"{}\".format(except_object))\n\nprint(\"{:d} was accepted\".format(x))",
      "execution_count": 4,
      "outputs": [
        {
          "output_type": "stream",
          "name": "stdout",
          "text": "Enter a number between 1 and 10: 1+5\ninvalid literal for int() with base 10: '1+5'\nEnter a number between 1 and 10: 7456\nThe number is outside of the acceptable range\nEnter a number between 1 and 10: 2\n2 was accepted\n"
        }
      ]
    },
    {
      "metadata": {},
      "cell_type": "markdown",
      "source": "#### Raising an exception in a function\n\nThe input validity test can be reorganized into a function that raises a `ValueError` exception without handling it. The calling function will receive  the raised exception and handle it.\n\nTest the code with the following inputs:\n* 100 (an out-of-range value that should raise the forced exception)\n* text (a string value that will cause the `int()` function to raise a different `ValueError`)\n* 4 (a valid number within the range)"
    },
    {
      "metadata": {
        "trusted": true
      },
      "cell_type": "code",
      "source": "def isValid(num):\n    if ((num < 1) or (num > 10)):\n        raise ValueError(\"The number is outside of the acceptable range\")\n    else:\n        return num\n\nvalid = False\nwhile not valid:\n    try:\n        x = int(input(\"Enter a number between 1 and 10: \"))\n        x = isValid(x)\n        valid = True\n    except ValueError as except_object:\n        print(\"{}\".format(except_object))\n\nprint(\"{:d} was accepted\".format(x))",
      "execution_count": 6,
      "outputs": [
        {
          "output_type": "stream",
          "name": "stdout",
          "text": "Enter a number between 1 and 10: 666\nThe number is outside of the acceptable range\nEnter a number between 1 and 10: -5\nThe number is outside of the acceptable range\nEnter a number between 1 and 10: 32\nThe number is outside of the acceptable range\nEnter a number between 1 and 10: 5+\ninvalid literal for int() with base 10: '5+'\nEnter a number between 1 and 10: 6\n6 was accepted\n"
        }
      ]
    },
    {
      "metadata": {},
      "cell_type": "markdown",
      "source": "---\n<font size=\"6\" color=\"#B24C00\"  face=\"verdana\"> <B>Task 4</B></font>\n\n## Raising Exceptions"
    },
    {
      "metadata": {},
      "cell_type": "markdown",
      "source": "### User input"
    },
    {
      "metadata": {
        "trusted": true
      },
      "cell_type": "code",
      "source": "# [ ] Write a program to keep prompting the user for an odd positive number until a valid number is entered.\n# Your program should raise an exception with an appropriate message if the input is not valid.\ndef isOdd(odd_num):\n    if odd_num < 0:\n        raise ValueError(\"Its not an positive number!!!!\")\n    elif odd_num % 2 ==0:\n        raise ValueError(\"Its not an odd number!!!!\")\n    else:\n        return odd_num\n\nvalid = False\nwhile not valid:\n    try:\n        num = int(input(\"Input an odd positive number:\"))\n        num = isOdd(num)\n        valid = True\n    except ValueError as except_object:\n        print(\"{}\".format(except_object))\n\nprint(\"{:d} was accepted\".format(num))",
      "execution_count": 12,
      "outputs": [
        {
          "output_type": "stream",
          "name": "stdout",
          "text": "Input an odd positive number:6\nIts not an odd number!!!!\nInput an odd positive number:78\nIts not an odd number!!!!\nInput an odd positive number:-5\nIts not an positive number!!!!\nInput an odd positive number:9\n9 was accepted\n"
        }
      ]
    },
    {
      "metadata": {
        "trusted": true
      },
      "cell_type": "code",
      "source": "# [ ] Complete the function `isValid` to test the validity of a user input. A valid input should be an odd positive integer.\n# The function should raise an exception with an appropriate message if the input is not valid.\n# The function need not handle the exception.\n\n\ndef isValid(num):\n    if num < 0:\n        raise ValueError(\"Its not an positive number!!!!\")\n    elif num % 2 ==0:\n        raise ValueError(\"Its not an odd number!!!!\")\n    else:\n        return num\nvalid = False\nwhile not valid:\n    try:\n        x = int(input(\"Enter an odd positive number: \"))\n        x = isValid(x)\n        valid = True\n    except ValueError as except_object:\n        print(\"{}\".format(except_object))\n\nprint(\"{:d} was accepted\".format(x))\n\n\n",
      "execution_count": 14,
      "outputs": [
        {
          "output_type": "stream",
          "name": "stdout",
          "text": "Enter an odd positive number: \ninvalid literal for int() with base 10: ''\nEnter an odd positive number: 5\n5 was accepted\n"
        }
      ]
    }
  ],
  "metadata": {
    "kernelspec": {
      "name": "python3",
      "display_name": "Python 3",
      "language": "python"
    },
    "language_info": {
      "mimetype": "text/x-python",
      "nbconvert_exporter": "python",
      "name": "python",
      "file_extension": ".py",
      "version": "3.5.4",
      "pygments_lexer": "ipython3",
      "codemirror_mode": {
        "version": 3,
        "name": "ipython"
      }
    }
  },
  "nbformat": 4,
  "nbformat_minor": 2
}